[I 200714 13:06:38 inrepo:36] Testing notebook 14 Descriptors.ipynb
[I 200714 13:06:38 inrepo:45] Found kernel python3
[I 200714 13:06:39 execute:404] Executing notebook with kernel: python3
Traceback (most recent call last):
  File "/src/inrepo.py", line 114, in <module>
    main()
  File "/src/inrepo.py", line 110, in main
    test_f(opts.test, opts.output_dir)
  File "/src/inrepo.py", line 75, in run_notebook
    nb, cwd=os.path.dirname(nb_path), kernel_name=kernel_name, timeout=600
  File "/srv/conda/envs/notebook/lib/python3.7/site-packages/nbconvert/preprocessors/execute.py", line 737, in executenb
    return ep.preprocess(nb, resources, km=km)[0]
  File "/srv/conda/envs/notebook/lib/python3.7/site-packages/nbconvert/preprocessors/execute.py", line 405, in preprocess
    nb, resources = super(ExecutePreprocessor, self).preprocess(nb, resources)
  File "/srv/conda/envs/notebook/lib/python3.7/site-packages/nbconvert/preprocessors/base.py", line 69, in preprocess
    nb.cells[index], resources = self.preprocess_cell(cell, resources, index)
  File "/srv/conda/envs/notebook/lib/python3.7/site-packages/nbconvert/preprocessors/execute.py", line 448, in preprocess_cell
    raise CellExecutionError.from_cell_and_msg(cell, out)
nbconvert.preprocessors.execute.CellExecutionError: An error occurred while executing the following cell:
------------------
m = MyClass('hi')
------------------

[0;31m---------------------------------------------------------------------------[0m
[0;31mValueError[0m                                Traceback (most recent call last)
[0;32m<ipython-input-3-8149b4ebea3b>[0m in [0;36mvalidate[0;34m(self, value)[0m
[1;32m      3[0m         [0;32mtry[0m[0;34m:[0m[0;34m[0m[0;34m[0m[0m
[0;32m----> 4[0;31m             [0mvalue[0m [0;34m=[0m [0mint[0m[0;34m([0m[0mvalue[0m[0;34m)[0m[0;34m[0m[0;34m[0m[0m
[0m[1;32m      5[0m         [0;32mexcept[0m [0mValueError[0m[0;34m:[0m[0;34m[0m[0;34m[0m[0m

[0;31mValueError[0m: invalid literal for int() with base 10: 'hi'

During handling of the above exception, another exception occurred:

[0;31mValueError[0m                                Traceback (most recent call last)
[0;32m<ipython-input-5-92726f467f48>[0m in [0;36m<module>[0;34m[0m
[0;32m----> 1[0;31m [0mm[0m [0;34m=[0m [0mMyClass[0m[0;34m([0m[0;34m'hi'[0m[0;34m)[0m[0;34m[0m[0;34m[0m[0m
[0m
[0;32m<ipython-input-4-524edd06514a>[0m in [0;36m__init__[0;34m(self, count)[0m
[1;32m      3[0m [0;34m[0m[0m
[1;32m      4[0m     [0;32mdef[0m [0m__init__[0m[0;34m([0m[0mself[0m[0;34m,[0m [0mcount[0m[0;34m)[0m[0;34m:[0m[0;34m[0m[0;34m[0m[0m
[0;32m----> 5[0;31m         [0mself[0m[0;34m.[0m[0mcount[0m [0;34m=[0m [0mcount[0m[0;34m[0m[0;34m[0m[0m
[0m
[0;32m<ipython-input-2-9f1ac9fdb1ca>[0m in [0;36m__set__[0;34m(self, instance, value)[0m
[1;32m      4[0m     [0;32mdef[0m [0m__set__[0m[0;34m([0m[0mself[0m[0;34m,[0m [0minstance[0m[0;34m,[0m [0mvalue[0m[0;34m)[0m[0;34m:[0m[0;34m[0m[0;34m[0m[0m
[1;32m      5[0m         [0mprint[0m[0;34m([0m[0;34m"Calling set"[0m[0;34m)[0m[0;34m[0m[0;34m[0m[0m
[0;32m----> 6[0;31m         [0mself[0m[0;34m.[0m[0mvalidate[0m[0;34m([0m[0mvalue[0m[0;34m)[0m[0;34m[0m[0;34m[0m[0m
[0m[1;32m      7[0m         [0msuper[0m[0;34m([0m[0;34m)[0m[0;34m.[0m[0m__set__[0m[0;34m([0m[0minstance[0m[0;34m,[0m [0mvalue[0m[0;34m)[0m[0;34m[0m[0;34m[0m[0m
[1;32m      8[0m [0;34m[0m[0m

[0;32m<ipython-input-3-8149b4ebea3b>[0m in [0;36mvalidate[0;34m(self, value)[0m
[1;32m      4[0m             [0mvalue[0m [0;34m=[0m [0mint[0m[0;34m([0m[0mvalue[0m[0;34m)[0m[0;34m[0m[0;34m[0m[0m
[1;32m      5[0m         [0;32mexcept[0m [0mValueError[0m[0;34m:[0m[0;34m[0m[0;34m[0m[0m
[0;32m----> 6[0;31m             [0;32mraise[0m [0mValueError[0m[0;34m([0m[0;34m'Invalid value for integer'[0m[0;34m)[0m[0;34m[0m[0;34m[0m[0m
[0m
[0;31mValueError[0m: Invalid value for integer
ValueError: Invalid value for integer


Container exited with status: {'Error': None, 'StatusCode': 1}
