[I 200706 08:44:33 inrepo:35] Testing notebook examples/TimeSliderChoropleth.ipynb
[I 200706 08:44:34 execute:404] Executing notebook with kernel: python3
Traceback (most recent call last):
  File "/src/inrepo.py", line 76, in <module>
    main()
  File "/src/inrepo.py", line 72, in main
    test_f(opts.test, opts.output_dir)
  File "/src/inrepo.py", line 38, in run_notebook
    exported = executenb(nb, cwd=os.path.dirname(nb_path))
  File "/srv/conda/envs/notebook/lib/python3.7/site-packages/nbconvert/preprocessors/execute.py", line 737, in executenb
    return ep.preprocess(nb, resources, km=km)[0]
  File "/srv/conda/envs/notebook/lib/python3.7/site-packages/nbconvert/preprocessors/execute.py", line 405, in preprocess
    nb, resources = super(ExecutePreprocessor, self).preprocess(nb, resources)
  File "/srv/conda/envs/notebook/lib/python3.7/site-packages/nbconvert/preprocessors/base.py", line 69, in preprocess
    nb.cells[index], resources = self.preprocess_cell(cell, resources, index)
  File "/srv/conda/envs/notebook/lib/python3.7/site-packages/nbconvert/preprocessors/execute.py", line 448, in preprocess_cell
    raise CellExecutionError.from_cell_and_msg(cell, out)
nbconvert.preprocessors.execute.CellExecutionError: An error occurred while executing the following cell:
------------------
%matplotlib inline

ax = gdf.plot(figsize=(10, 10))
------------------

[0;31m---------------------------------------------------------------------------[0m
[0;31mModuleNotFoundError[0m                       Traceback (most recent call last)
[0;32m/srv/conda/envs/notebook/lib/python3.7/site-packages/geopandas/plotting.py[0m in [0;36m_plot_polygon_collection[0;34m(ax, geoms, values, color, cmap, vmin, vmax, **kwargs)[0m
[1;32m    119[0m     [0;32mtry[0m[0;34m:[0m[0;34m[0m[0;34m[0m[0m
[0;32m--> 120[0;31m         [0;32mfrom[0m [0mdescartes[0m[0;34m.[0m[0mpatch[0m [0;32mimport[0m [0mPolygonPatch[0m[0;34m[0m[0;34m[0m[0m
[0m[1;32m    121[0m     [0;32mexcept[0m [0mImportError[0m[0;34m:[0m[0;34m[0m[0;34m[0m[0m

[0;31mModuleNotFoundError[0m: No module named 'descartes'

During handling of the above exception, another exception occurred:

[0;31mImportError[0m                               Traceback (most recent call last)
[0;32m<ipython-input-3-423c72b95e2e>[0m in [0;36m<module>[0;34m[0m
[1;32m      1[0m [0mget_ipython[0m[0;34m([0m[0;34m)[0m[0;34m.[0m[0mrun_line_magic[0m[0;34m([0m[0;34m'matplotlib'[0m[0;34m,[0m [0;34m'inline'[0m[0;34m)[0m[0;34m[0m[0;34m[0m[0m
[1;32m      2[0m [0;34m[0m[0m
[0;32m----> 3[0;31m [0max[0m [0;34m=[0m [0mgdf[0m[0;34m.[0m[0mplot[0m[0;34m([0m[0mfigsize[0m[0;34m=[0m[0;34m([0m[0;36m10[0m[0;34m,[0m [0;36m10[0m[0;34m)[0m[0;34m)[0m[0;34m[0m[0;34m[0m[0m
[0m
[0;32m/srv/conda/envs/notebook/lib/python3.7/site-packages/geopandas/geodataframe.py[0m in [0;36mplot[0;34m(self, *args, **kwargs)[0m
[1;32m    897[0m         [0;32mfrom[0m [0mthere[0m[0;34m.[0m[0;34m[0m[0;34m[0m[0m
[1;32m    898[0m         """
[0;32m--> 899[0;31m         [0;32mreturn[0m [0mplot_dataframe[0m[0;34m([0m[0mself[0m[0;34m,[0m [0;34m*[0m[0margs[0m[0;34m,[0m [0;34m**[0m[0mkwargs[0m[0;34m)[0m[0;34m[0m[0;34m[0m[0m
[0m[1;32m    900[0m [0;34m[0m[0m
[1;32m    901[0m     [0mplot[0m[0;34m.[0m[0m__doc__[0m [0;34m=[0m [0mplot_dataframe[0m[0;34m.[0m[0m__doc__[0m[0;34m[0m[0;34m[0m[0m

[0;32m/srv/conda/envs/notebook/lib/python3.7/site-packages/geopandas/plotting.py[0m in [0;36mplot_dataframe[0;34m(df, column, cmap, color, ax, cax, categorical, legend, scheme, k, vmin, vmax, markersize, figsize, legend_kwds, categories, classification_kwds, missing_kwds, aspect, **style_kwds)[0m
[1;32m    621[0m             [0mmarkersize[0m[0;34m=[0m[0mmarkersize[0m[0;34m,[0m[0;34m[0m[0;34m[0m[0m
[1;32m    622[0m             [0maspect[0m[0;34m=[0m[0maspect[0m[0;34m,[0m[0;34m[0m[0;34m[0m[0m
[0;32m--> 623[0;31m             [0;34m**[0m[0mstyle_kwds[0m[0;34m[0m[0;34m[0m[0m
[0m[1;32m    624[0m         )
[1;32m    625[0m [0;34m[0m[0m

[0;32m/srv/conda/envs/notebook/lib/python3.7/site-packages/geopandas/plotting.py[0m in [0;36mplot_series[0;34m(s, cmap, color, ax, figsize, aspect, **style_kwds)[0m
[1;32m    412[0m         [0mvalues_[0m [0;34m=[0m [0mvalues[0m[0;34m[[0m[0mpoly_idx[0m[0;34m][0m [0;32mif[0m [0mcmap[0m [0;32melse[0m [0;32mNone[0m[0;34m[0m[0;34m[0m[0m
[1;32m    413[0m         _plot_polygon_collection(
[0;32m--> 414[0;31m             [0max[0m[0;34m,[0m [0mpolys[0m[0;34m,[0m [0mvalues_[0m[0;34m,[0m [0mfacecolor[0m[0;34m=[0m[0mfacecolor[0m[0;34m,[0m [0mcmap[0m[0;34m=[0m[0mcmap[0m[0;34m,[0m [0;34m**[0m[0mstyle_kwds[0m[0;34m[0m[0;34m[0m[0m
[0m[1;32m    415[0m         )
[1;32m    416[0m [0;34m[0m[0m

[0;32m/srv/conda/envs/notebook/lib/python3.7/site-packages/geopandas/plotting.py[0m in [0;36m_plot_polygon_collection[0;34m(ax, geoms, values, color, cmap, vmin, vmax, **kwargs)[0m
[1;32m    121[0m     [0;32mexcept[0m [0mImportError[0m[0;34m:[0m[0;34m[0m[0;34m[0m[0m
[1;32m    122[0m         raise ImportError(
[0;32m--> 123[0;31m             [0;34m"The descartes package is required for plotting polygons in geopandas. "[0m[0;34m[0m[0;34m[0m[0m
[0m[1;32m    124[0m             [0;34m"You can install it using 'conda install -c conda-forge descartes' or "[0m[0;34m[0m[0;34m[0m[0m
[1;32m    125[0m             [0;34m"'pip install descartes'."[0m[0;34m[0m[0;34m[0m[0m

[0;31mImportError[0m: The descartes package is required for plotting polygons in geopandas. You can install it using 'conda install -c conda-forge descartes' or 'pip install descartes'.
ImportError: The descartes package is required for plotting polygons in geopandas. You can install it using 'conda install -c conda-forge descartes' or 'pip install descartes'.


Container exited with status: {'Error': None, 'StatusCode': 1}
