[I 200703 10:25:39 inrepo:35] Testing notebook docs/notebooks/GeneralizationExperiments.ipynb
[I 200703 10:25:40 execute:404] Executing notebook with kernel: python3
Traceback (most recent call last):
  File "/src/inrepo.py", line 76, in <module>
    main()
  File "/src/inrepo.py", line 72, in main
    test_f(opts.test, opts.output_dir)
  File "/src/inrepo.py", line 38, in run_notebook
    exported = executenb(nb, cwd=os.path.dirname(nb_path))
  File "/srv/conda/envs/notebook/lib/python3.7/site-packages/nbconvert/preprocessors/execute.py", line 737, in executenb
    return ep.preprocess(nb, resources, km=km)[0]
  File "/srv/conda/envs/notebook/lib/python3.7/site-packages/nbconvert/preprocessors/execute.py", line 405, in preprocess
    nb, resources = super(ExecutePreprocessor, self).preprocess(nb, resources)
  File "/srv/conda/envs/notebook/lib/python3.7/site-packages/nbconvert/preprocessors/base.py", line 69, in preprocess
    nb.cells[index], resources = self.preprocess_cell(cell, resources, index)
  File "/srv/conda/envs/notebook/lib/python3.7/site-packages/nbconvert/preprocessors/execute.py", line 448, in preprocess_cell
    raise CellExecutionError.from_cell_and_msg(cell, out)
nbconvert.preprocessors.execute.CellExecutionError: An error occurred while executing the following cell:
------------------
import warnings
warnings.filterwarnings('ignore')
import inspect
import os
import logging
import numpy as np
import pandas as pd
from docopt import docopt
from csrank import FATEObjectRanker, FETAObjectRanker, ObjectRankingDatasetGenerator
from csrank.callbacks import DebugOutput
from csrank.metrics import zero_one_rank_loss_for_scores
from csrank.util import rename_file_if_exist, configure_logging_numpy_keras, get_tensor_value
from keras.callbacks import History
------------------

[0;31m---------------------------------------------------------------------------[0m
[0;31mImportError[0m                               Traceback (most recent call last)
[0;32m<ipython-input-1-a7304aadb775>[0m in [0;36m<module>[0;34m[0m
[1;32m     10[0m [0;32mfrom[0m [0mcsrank[0m[0;34m.[0m[0mcallbacks[0m [0;32mimport[0m [0mDebugOutput[0m[0;34m[0m[0;34m[0m[0m
[1;32m     11[0m [0;32mfrom[0m [0mcsrank[0m[0;34m.[0m[0mmetrics[0m [0;32mimport[0m [0mzero_one_rank_loss_for_scores[0m[0;34m[0m[0;34m[0m[0m
[0;32m---> 12[0;31m [0;32mfrom[0m [0mcsrank[0m[0;34m.[0m[0mutil[0m [0;32mimport[0m [0mrename_file_if_exist[0m[0;34m,[0m [0mconfigure_logging_numpy_keras[0m[0;34m,[0m [0mget_tensor_value[0m[0;34m[0m[0;34m[0m[0m
[0m[1;32m     13[0m [0;32mfrom[0m [0mkeras[0m[0;34m.[0m[0mcallbacks[0m [0;32mimport[0m [0mHistory[0m[0;34m[0m[0;34m[0m[0m

[0;31mImportError[0m: cannot import name 'configure_logging_numpy_keras' from 'csrank.util' (/srv/conda/envs/notebook/lib/python3.7/site-packages/csrank/util.py)
ImportError: cannot import name 'configure_logging_numpy_keras' from 'csrank.util' (/srv/conda/envs/notebook/lib/python3.7/site-packages/csrank/util.py)


Container exited with status: {'Error': None, 'StatusCode': 1}
