[I 200703 08:29:01 inrepo:35] Testing notebook docs/examples/working_notebook.ipynb
[I 200703 08:29:02 execute:404] Executing notebook with kernel: python3
Traceback (most recent call last):
  File "/src/inrepo.py", line 76, in <module>
    main()
  File "/src/inrepo.py", line 72, in main
    test_f(opts.test, opts.output_dir)
  File "/src/inrepo.py", line 38, in run_notebook
    exported = executenb(nb, cwd=os.path.dirname(nb_path))
  File "/srv/conda/envs/notebook/lib/python3.7/site-packages/nbconvert/preprocessors/execute.py", line 737, in executenb
    return ep.preprocess(nb, resources, km=km)[0]
  File "/srv/conda/envs/notebook/lib/python3.7/site-packages/nbconvert/preprocessors/execute.py", line 405, in preprocess
    nb, resources = super(ExecutePreprocessor, self).preprocess(nb, resources)
  File "/srv/conda/envs/notebook/lib/python3.7/site-packages/nbconvert/preprocessors/base.py", line 69, in preprocess
    nb.cells[index], resources = self.preprocess_cell(cell, resources, index)
  File "/srv/conda/envs/notebook/lib/python3.7/site-packages/nbconvert/preprocessors/execute.py", line 450, in preprocess_cell
    raise CellExecutionError.from_cell_and_msg(cell, reply['content'])
nbconvert.preprocessors.execute.CellExecutionError: An error occurred while executing the following cell:
------------------
% E=7.31e10;
% I=1/12*.03*.015^3;
% rho=2747;
% A=.015*.03;
% L=0.4;
------------------


UsageError: Line magic function `%` not found.


Container exited with status: {'Error': None, 'StatusCode': 1}
