[I 200712 19:18:43 inrepo:36] Testing notebook jupyter notebook/å­—ç¬¦ä¸²å’Œæ–‡æœ¬.ipynb
[I 200712 19:18:43 inrepo:45] Found kernel python3
[I 200712 19:18:44 execute:404] Executing notebook with kernel: python3
Traceback (most recent call last):
  File "/src/inrepo.py", line 114, in <module>
    main()
  File "/src/inrepo.py", line 110, in main
    test_f(opts.test, opts.output_dir)
  File "/src/inrepo.py", line 75, in run_notebook
    nb, cwd=os.path.dirname(nb_path), kernel_name=kernel_name, timeout=600
  File "/srv/conda/envs/notebook/lib/python3.7/site-packages/nbconvert/preprocessors/execute.py", line 737, in executenb
    return ep.preprocess(nb, resources, km=km)[0]
  File "/srv/conda/envs/notebook/lib/python3.7/site-packages/nbconvert/preprocessors/execute.py", line 405, in preprocess
    nb, resources = super(ExecutePreprocessor, self).preprocess(nb, resources)
  File "/srv/conda/envs/notebook/lib/python3.7/site-packages/nbconvert/preprocessors/base.py", line 69, in preprocess
    nb.cells[index], resources = self.preprocess_cell(cell, resources, index)
  File "/srv/conda/envs/notebook/lib/python3.7/site-packages/nbconvert/preprocessors/execute.py", line 448, in preprocess_cell
    raise CellExecutionError.from_cell_and_msg(cell, out)
nbconvert.preprocessors.execute.CellExecutionError: An error occurred while executing the following cell:
------------------
choices = ['https:','ftp:']
url = 'https://www.python.org'
url.startswith(choices)
------------------

[0;31m---------------------------------------------------------------------------[0m
[0;31mTypeError[0m                                 Traceback (most recent call last)
[0;32m<ipython-input-19-1670d3574247>[0m in [0;36m<module>[0;34m[0m
[1;32m      1[0m [0mchoices[0m [0;34m=[0m [0;34m[[0m[0;34m'https:'[0m[0;34m,[0m[0;34m'ftp:'[0m[0;34m][0m[0;34m[0m[0;34m[0m[0m
[1;32m      2[0m [0murl[0m [0;34m=[0m [0;34m'https://www.python.org'[0m[0;34m[0m[0;34m[0m[0m
[0;32m----> 3[0;31m [0murl[0m[0;34m.[0m[0mstartswith[0m[0;34m([0m[0mchoices[0m[0;34m)[0m[0;34m[0m[0;34m[0m[0m
[0m
[0;31mTypeError[0m: startswith first arg must be str or a tuple of str, not list
TypeError: startswith first arg must be str or a tuple of str, not list


Container exited with status: {'Error': None, 'StatusCode': 1}
